<robot name="simple_robot"> <!--  robot name- you decide   -->
<!--  sequence : link-joint-link-joint- ... -link    -->
<!--  first link called base_link --> 
<!--  units: meters for distance, rad in case of angles -->  
<link name="base_link">
    <visual>
      <geometry>
        <cylinder length="0.01" radius="0.2"/> 
      </geometry>
      <origin rpy="0 0 0" xyz="0 0 0"/> <!--  rpy: roll pitch yaw -> orientation xyz> position --> 
      <material name="generic">
        <color rgba="1 1 0 1"/>
      </material>
    </visual>
  </link>
<!--  first joint --> 
  <joint name="joint1" type="revolute"> <!--  types: revolute and prismatic --> 
    <parent link="base_link"/>
    <child link="link1"/>
    <origin xyz="0 0 0"/>
    <axis xyz="0 0 1"/>
    <limit effort="300" velocity="0.1" lower="-3.14" upper="3.14"/>
    <dynamics damping="50" friction="1"/>
  </joint>
<!--  link 1--> 
  <link name="link1">
    <visual>
      <geometry>
        <cylinder length="0.65" radius="0.04"/>
      </geometry>
      <origin rpy="0 0 0" xyz="0 0 0.315"/>
      <material name="generic_2">
        <color rgba="0 1 1 1"/>
      </material>
    </visual>
  </link>
<!--  joint 2--> 
  <joint name="joint2" type="prismatic">
    <parent link="link1"/>
    <child link="link2"/>
    <origin xyz="0 0 0.65"/>
    <axis xyz="-1 0 0"/>
    <limit effort="300" velocity="0.1" lower="-0.2" upper="0.2"/>
    <dynamics damping="50" friction="1"/>
  </joint>
  <link name="link2">
    <visual>
      <geometry>
        <box size="0.25 0.03 0.03"/>
      </geometry>
      <origin rpy="0 0 0" xyz="0.15 0 0"/>
      <material name="generic_5">
        <color rgba="1 0 0 1"/>
      </material>
    </visual>
  </link>
<!--  joint 3--> 
  <joint name="joint3" type="revolute">
    <parent link="link2"/>
    <child link="link3"/>
    <origin xyz="0.25 0 0"/>
    <axis xyz="0 0 -1"/>
    <limit effort="300" velocity="0.1" lower="-3.14" upper="3.14"/>
    <dynamics damping="50" friction="1"/>
  </joint>
<!--  link 3--> 
  <link name="link3">
    <visual>
      <geometry>
        <cylinder length="0.38" radius="0.03"/>
      </geometry>
      <origin rpy="0 0 1.5708" xyz="0 0 0.2"/>
      <material name="generic_4">
        <color rgba="0 1 0 1"/>
      </material>
    </visual>
  </link>
<!--  link 4--> 
  <joint name="joint4" type="revolute">
    <parent link="link3"/>
    <child link="link4"/>
    <origin xyz="0 0 0.38"/>
    <axis xyz="1 0 0"/>
    <limit effort="300" velocity="0.1" lower="-3.14" upper="3.14"/>
    <dynamics damping="50" friction="1"/>
  </joint>
  <link name="link4">
    <visual>
      <geometry>
        <cylinder length="0.42" radius="0.04"/>
      </geometry>
      <origin rpy="0 1.57079 0" xyz="0.2 0 0"/>
      <material name="generic_2">
        <color rgba="0 0 1 1"/>
      </material>
    </visual>
  </link>

<!-- link extra-->
  <joint name="joint5" type="revolute">
    <parent link="link4"/>
    <child link="link5"/>
    <origin xyz="0.42 0 0"/>
    <axis xyz="1 0 0"/>
    <limit effort="300" velocity="0.1" lower="-3.14" upper="3.14"/>
    <dynamics damping="50" friction="1"/>
  </joint>
  <link name="link5">
    <visual>
      <geometry>
        <cylinder length="0" radius="0.04"/>
      </geometry>
      <origin rpy="0 1.57079 0" xyz="0.15 0 0"/>
      <material name="generic_2">
        <color rgba="0 0 1 1"/>
      </material>
    </visual>
  </link>
</robot>
